<?xml version="1.0"?>
<robot name="vehicle_blue">
  <material name="blue">
    <color rgba="0.0 0.0 1.0 1.0"/>
  </material>

  <material name="red">
    <color rgba="1.0 0.0 0.0 1.0"/>
  </material>

  <material name="green">
    <color rgba="0.0 1.0 0.0 1.0"/>
  </material>

  <gazebo>
    <plugin filename="libgz_ros2_control-system.so"
            name="gz_ros2_control::GazeboSimROS2ControlPlugin">
      <parameters>/home/user/ros2_ws/install/my_package/share/my_package/config/controllers.yaml</parameters>
      <controller_manager_name>controller_manager</controller_manager_name>
    </plugin>
  </gazebo>

  <!-- Wheel friction -->
  <gazebo reference="front_left_wheel">
    <collision>
      <surface>
        <friction>
          <ode>
            <mu>1.5</mu>
            <mu2>0.02</mu2>
            <fdir1 gz:expressed_in="chassis">1 -1 0</fdir1>
            <slip1>0.0</slip1>
            <slip2>0.0</slip2>
          </ode>
        </friction>
        <contact>
          <ode>
            <kp>1000000.0</kp>
            <kd>100.0</kd>
          </ode>
        </contact>
      </surface>
    </collision>
  </gazebo>

  <gazebo reference="front_right_wheel">
    <collision>
      <surface>
        <friction>
          <ode>
            <mu>1.5</mu>
            <mu2>0.02</mu2>
            <fdir1 gz:expressed_in="chassis">1 1 0</fdir1>
            <slip1>0.0</slip1>
            <slip2>0.0</slip2>
          </ode>
        </friction>
        <contact>
          <ode>
            <kp>1000000.0</kp>
            <kd>100.0</kd>
          </ode>
        </contact>
      </surface>
    </collision>
  </gazebo>

  <gazebo reference="rear_left_wheel">
    <collision>
      <surface>
        <friction>
          <ode>
            <mu>1.5</mu>
            <mu2>0.02</mu2>
            <fdir1 gz:expressed_in="chassis">1 1 0</fdir1>
            <slip1>0.0</slip1>
            <slip2>0.0</slip2>
          </ode>
        </friction>
        <contact>
          <ode>
            <kp>1000000.0</kp>
            <kd>100.0</kd>
          </ode>
        </contact>
      </surface>
    </collision>
  </gazebo>

  <gazebo reference="rear_right_wheel">
    <collision>
      <surface>
        <friction>
          <ode>
            <mu>1.5</mu>
            <mu2>0.02</mu2>
            <fdir1 gz:expressed_in="chassis">1 -1 0</fdir1>
            <slip1>0.0</slip1>
            <slip2>0.0</slip2>
          </ode>
        </friction>
        <contact>
          <ode>
            <kp>1000000.0</kp>
            <kd>100.0</kd>
          </ode>
        </contact>
      </surface>
    </collision>
  </gazebo>

  <!-- Chassis -->
  <link name="chassis">
    <inertial>
      <origin xyz="0 0 0" rpy="0 0 0"/>
      <mass value="1.0"/>
      <inertia
        ixx="0.02"
        ixy="0"
        ixz="0"
        iyy="0.05"
        iyz="0"
        izz="0.06"/>
    </inertial>

    <visual>
      <origin xyz="0 0 0" rpy="0 0 0"/>
      <geometry>
        <box size="1.0 0.5 0.25"/>
      </geometry>
      <material name="blue"/>
    </visual>

    <collision>
      <origin xyz="0 0 0" rpy="0 0 0"/>
      <geometry>
        <box size="1.0 0.5 0.25"/>
      </geometry>
    </collision>
  </link>

  <!-- Front Left Wheel -->
  <link name="front_left_wheel">
    <inertial>
      <origin xyz="0 0 0" rpy="0 0 0"/>
      <mass value="0.2"/>
      <inertia
        ixx="0.001"
        ixy="0"
        ixz="0"
        iyy="0.001"
        iyz="0"
        izz="0.0015"/>
    </inertial>

    <visual>
      <origin xyz="0 0 0" rpy="0 0 0"/>
      <geometry>
        <cylinder radius="0.2" length="0.1"/>
      </geometry>
      <material name="red"/>
    </visual>

    <collision>
      <origin xyz="0 0 0" rpy="0 0 0"/>
      <geometry>
        <cylinder radius="0.2" length="0.1"/>
      </geometry>
    </collision>
  </link>

  <joint name="front_left_wheel_joint" type="continuous">
    <parent link="chassis"/>
    <child link="front_left_wheel"/>
    <origin xyz="0.3 0.3 0" rpy="-1.5707 0 0"/>
    <axis xyz="0 0 1"/>
  </joint>

  <!-- Front Right Wheel -->
  <link name="front_right_wheel">
    <inertial>
      <origin xyz="0 0 0" rpy="0 0 0"/>
      <mass value="0.2"/>
      <inertia
        ixx="0.001"
        ixy="0"
        ixz="0"
        iyy="0.001"
        iyz="0"
        izz="0.0015"/>
    </inertial>

    <visual>
      <origin xyz="0 0 0" rpy="0 0 0"/>
      <geometry>
        <cylinder radius="0.2" length="0.1"/>
      </geometry>
      <material name="red"/>
    </visual>

    <collision>
      <origin xyz="0 0 0" rpy="0 0 0"/>
      <geometry>
        <cylinder radius="0.2" length="0.1"/>
      </geometry>
    </collision>
  </link>

  <joint name="front_right_wheel_joint" type="continuous">
    <parent link="chassis"/>
    <child link="front_right_wheel"/>
    <origin xyz="0.3 -0.3 0" rpy="-1.5707 0 0"/>
    <axis xyz="0 0 1"/>
  </joint>

  <!-- Rear Left Wheel -->
  <link name="rear_left_wheel">
    <inertial>
      <origin xyz="0 0 0" rpy="0 0 0"/>
      <mass value="0.2"/>
      <inertia
        ixx="0.001"
        ixy="0"
        ixz="0"
        iyy="0.001"
        iyz="0"
        izz="0.0015"/>
    </inertial>

    <visual>
      <origin xyz="0 0 0" rpy="0 0 0"/>
      <geometry>
        <cylinder radius="0.2" length="0.1"/>
      </geometry>
      <material name="red"/>
    </visual>

    <collision>
      <origin xyz="0 0 0" rpy="0 0 0"/>
      <geometry>
        <cylinder radius="0.2" length="0.1"/>
      </geometry>
    </collision>
  </link>

  <joint name="rear_left_wheel_joint" type="continuous">
    <parent link="chassis"/>
    <child link="rear_left_wheel"/>
    <origin xyz="-0.3 0.3 0" rpy="-1.5707 0 0"/>
    <axis xyz="0 0 1"/>
  </joint>

  <!-- Rear Right Wheel -->
  <link name="rear_right_wheel">
    <inertial>
      <origin xyz="0 0 0" rpy="0 0 0"/>
      <mass value="0.2"/>
      <inertia
        ixx="0.001"
        ixy="0"
        ixz="0"
        iyy="0.001"
        iyz="0"
        izz="0.0015"/>
    </inertial>

    <visual>
      <origin xyz="0 0 0" rpy="0 0 0"/>
      <geometry>
        <cylinder radius="0.2" length="0.1"/>
      </geometry>
      <material name="red"/>
    </visual>

    <collision>
      <origin xyz="0 0 0" rpy="0 0 0"/>
      <geometry>
        <cylinder radius="0.2" length="0.1"/>
      </geometry>
    </collision>
  </link>

  <joint name="rear_right_wheel_joint" type="continuous">
    <parent link="chassis"/>
    <child link="rear_right_wheel"/>
    <origin xyz="-0.3 -0.3 0" rpy="-1.5707 0 0"/>
    <axis xyz="0 0 1"/>
  </joint>

  <!-- LiDAR -->
  <link name="lidar_link">
    <inertial>
      <origin xyz="0 0 0" rpy="0 0 0"/>
      <mass value="0.05"/>
      <inertia
        ixx="0.0001"
        ixy="0.0"
        ixz="0.0"
        iyy="0.0001"
        iyz="0.0"
        izz="0.0001"/>
    </inertial>

    <visual>
      <origin xyz="0 0 0" rpy="0 0 0"/>
      <geometry>
        <cylinder radius="0.03" length="0.04"/>
      </geometry>
      <material name="green"/>
    </visual>

    <collision>
      <origin xyz="0 0 0" rpy="0 0 0"/>
      <geometry>
        <cylinder radius="0.03" length="0.04"/>
      </geometry>
    </collision>
  </link>

  <joint name="lidar_joint" type="fixed">
    <parent link="chassis"/>
    <child link="lidar_link"/>
    <!-- slightly forward and above the chassis center -->
    <origin xyz="0.40 0.0 0.18" rpy="0 0 0"/>
  </joint>

  <gazebo reference="lidar_link">
    <sensor name="lidar_sensor" type="gpu_lidar">
      <topic>scan</topic>
      
      <gz_frame_id>lidar_link</gz_frame_id>

      <update_rate>10</update_rate>
      <always_on>true</always_on>
      <visualize>true</visualize>
      <ray>
        <scan>
          <horizontal>
            <samples>640</samples>
            <resolution>1</resolution>
            <min_angle>-1.5708</min_angle>
            <max_angle>1.5708</max_angle>
          </horizontal>
          <vertical>
            <samples>1</samples>
            <resolution>0.01</resolution>
            <min_angle>0.0</min_angle>
            <max_angle>0.0</max_angle>
          </vertical>
        </scan>
        <range>
          <min>0.08</min>
          <max>10.0</max>
          <resolution>0.01</resolution>
        </range>
      </ray>
    </sensor>
  </gazebo>

  <ros2_control name="GazeboSimSystem" type="system">
    <hardware>
      <plugin>gz_ros2_control/GazeboSimSystem</plugin>
    </hardware>

    <joint name="front_left_wheel_joint">
      <command_interface name="velocity">
        <param name="min">-10.0</param>
        <param name="max">10.0</param>
      </command_interface>
      <state_interface name="position"/>
      <state_interface name="velocity"/>
    </joint>

    <joint name="front_right_wheel_joint">
      <command_interface name="velocity">
        <param name="min">-10.0</param>
        <param name="max">10.0</param>
      </command_interface>
      <state_interface name="position"/>
      <state_interface name="velocity"/>
    </joint>

    <joint name="rear_left_wheel_joint">
      <command_interface name="velocity">
        <param name="min">-10.0</param>
        <param name="max">10.0</param>
      </command_interface>
      <state_interface name="position"/>
      <state_interface name="velocity"/>
    </joint>

    <joint name="rear_right_wheel_joint">
      <command_interface name="velocity">
        <param name="min">-10.0</param>
        <param name="max">10.0</param>
      </command_interface>
      <state_interface name="position"/>
      <state_interface name="velocity"/>
    </joint>
  </ros2_control>
</robot>